2025-06-06 19:59:48,091 - pulseway_backend.logging_config - INFO [None] - setup_logging:86 - {'log_level': 'INFO', 'event': 'Logging setup complete.', 'logger': 'pulseway_backend.logging_config', 'level': 'info', 'timestamp': '2025-06-06T19:59:48.090962Z'}
2025-06-06 19:59:48,240 - sentry_init - WARNING [None] - <module>:48 - {'event': 'Sentry DSN not found, Sentry will not be initialized.', 'logger': 'sentry_init', 'level': 'warning', 'timestamp': '2025-06-06T19:59:48.240840Z'}
2025-06-06 19:59:48,241 - pulseway_backend.logging_config - INFO [None] - setup_logging:86 - {'log_level': 'INFO', 'event': 'Logging setup complete.', 'logger': 'pulseway_backend.logging_config', 'level': 'info', 'timestamp': '2025-06-06T19:59:48.241486Z'}
2025-06-06 20:00:12,087 - pulseway_backend.logging_config - INFO [None] - setup_logging:86 - {'log_level': 'INFO', 'event': 'Logging setup complete.', 'logger': 'pulseway_backend.logging_config', 'level': 'info', 'timestamp': '2025-06-06T20:00:12.087020Z'}
2025-06-06 20:00:57,914 - pulseway_backend.logging_config - INFO [None] - setup_logging:86 - {'log_level': 'INFO', 'event': 'Logging setup complete.', 'logger': 'pulseway_backend.logging_config', 'level': 'info', 'timestamp': '2025-06-06T20:00:57.914769Z'}
2025-06-06 20:00:58,222 - backend.app.main - WARNING [None] - verify_api_key:66 - {'event': 'Failed API key verification attempt.', 'request_id': 'cf0545c8-38ac-409d-b108-6d3a691d5ae9', 'logger': 'backend.app.main', 'level': 'warning', 'timestamp': '2025-06-06T20:00:58.222588Z'}
2025-06-06 20:00:58,225 - httpx - INFO [None] - _send_single_request:1013 - HTTP Request: GET http://testserver/test_exc/database_error "HTTP/1.1 401 Unauthorized"
2025-06-06 20:00:58,307 - backend.app.main - WARNING [None] - verify_api_key:66 - {'event': 'Failed API key verification attempt.', 'request_id': '4af2ea44-4aec-4aba-a5f1-6c5562aa9287', 'logger': 'backend.app.main', 'level': 'warning', 'timestamp': '2025-06-06T20:00:58.307112Z'}
2025-06-06 20:00:58,309 - httpx - INFO [None] - _send_single_request:1013 - HTTP Request: GET http://testserver/test_exc/external_api_error "HTTP/1.1 401 Unauthorized"
2025-06-06 20:00:58,317 - backend.app.main - WARNING [None] - verify_api_key:66 - {'event': 'Failed API key verification attempt.', 'request_id': '1a75ae73-6b0c-4df7-9dbc-cd3c615bf316', 'logger': 'backend.app.main', 'level': 'warning', 'timestamp': '2025-06-06T20:00:58.317276Z'}
2025-06-06 20:00:58,319 - httpx - INFO [None] - _send_single_request:1013 - HTTP Request: GET http://testserver/test_exc/authentication_error "HTTP/1.1 401 Unauthorized"
2025-06-06 20:00:58,330 - backend.app.main - WARNING [None] - verify_api_key:66 - {'event': 'Failed API key verification attempt.', 'request_id': '2d7259a7-987c-4349-810e-a8b8c554aae7', 'logger': 'backend.app.main', 'level': 'warning', 'timestamp': '2025-06-06T20:00:58.330793Z'}
2025-06-06 20:00:58,333 - httpx - INFO [None] - _send_single_request:1013 - HTTP Request: GET http://testserver/test_exc/not_found_error "HTTP/1.1 401 Unauthorized"
2025-06-06 20:00:58,341 - backend.app.main - WARNING [None] - verify_api_key:66 - {'event': 'Failed API key verification attempt.', 'request_id': '9a6d1ed0-11a1-4341-8c3c-afed007a09e8', 'logger': 'backend.app.main', 'level': 'warning', 'timestamp': '2025-06-06T20:00:58.341683Z'}
2025-06-06 20:00:58,344 - httpx - INFO [None] - _send_single_request:1013 - HTTP Request: GET http://testserver/test_exc/business_logic_error "HTTP/1.1 401 Unauthorized"
2025-06-06 20:00:58,352 - backend.app.main - WARNING [None] - verify_api_key:66 - {'event': 'Failed API key verification attempt.', 'request_id': 'fe987977-ce68-4a96-8a96-2ca7dcaae557', 'logger': 'backend.app.main', 'level': 'warning', 'timestamp': '2025-06-06T20:00:58.352905Z'}
2025-06-06 20:00:58,355 - httpx - INFO [None] - _send_single_request:1013 - HTTP Request: GET http://testserver/test_exc/app_exception_generic "HTTP/1.1 401 Unauthorized"
2025-06-06 20:00:58,363 - backend.app.main - WARNING [None] - verify_api_key:66 - {'event': 'Failed API key verification attempt.', 'request_id': '5a1a4fc5-0c3a-4096-9dbc-42649962e47b', 'logger': 'backend.app.main', 'level': 'warning', 'timestamp': '2025-06-06T20:00:58.363544Z'}
2025-06-06 20:00:58,365 - httpx - INFO [None] - _send_single_request:1013 - HTTP Request: GET http://testserver/ "HTTP/1.1 401 Unauthorized"
2025-06-06 20:00:58,371 - httpx - INFO [None] - _send_single_request:1013 - HTTP Request: GET http://testserver/ "HTTP/1.1 401 Unauthorized"
2025-06-06 20:02:21,639 - pulseway_backend.logging_config - INFO [None] - setup_logging:86 - {'log_level': 'INFO', 'event': 'Logging setup complete.', 'logger': 'pulseway_backend.logging_config', 'level': 'info', 'timestamp': '2025-06-06T20:02:21.639908Z'}
2025-06-06 20:02:21,902 - backend.app.main - ERROR [None] - app_exception_handler:134 - {'type': 'DatabaseError', 'detail': 'Test DB Error', 'status_code': 503, 'path': '/test_exc/database_error', 'method': 'GET', 'event': 'Application error occurred', 'request_id': '74bc6ff2-882e-4d3d-b5e8-a058725ce1b9', 'logger': 'backend.app.main', 'level': 'error', 'timestamp': '2025-06-06T20:02:21.900099Z', 'exception': 'Traceback (most recent call last):\n  File "/home/swebot/.local/lib/python3.10/site-packages/starlette/middleware/exceptions.py", line 68, in __call__\n    await self.app(scope, receive, sender)\n  File "/home/swebot/.local/lib/python3.10/site-packages/fastapi/middleware/asyncexitstack.py", line 20, in __call__\n    raise e\n  File "/home/swebot/.local/lib/python3.10/site-packages/fastapi/middleware/asyncexitstack.py", line 17, in __call__\n    await self.app(scope, receive, send)\n  File "/home/swebot/.local/lib/python3.10/site-packages/starlette/routing.py", line 718, in __call__\n    await route.handle(scope, receive, send)\n  File "/home/swebot/.local/lib/python3.10/site-packages/starlette/routing.py", line 276, in handle\n    await self.app(scope, receive, send)\n  File "/home/swebot/.local/lib/python3.10/site-packages/starlette/routing.py", line 66, in app\n    response = await func(request)\n  File "/home/swebot/.local/lib/python3.10/site-packages/fastapi/routing.py", line 274, in app\n    raw_response = await run_endpoint_function(\n  File "/home/swebot/.local/lib/python3.10/site-packages/fastapi/routing.py", line 191, in run_endpoint_function\n    return await dependant.call(**values)\n  File "/app/backend/tests/integration/test_main_exception_handling.py", line 28, in route_raises_database_error\n    raise DatabaseError(detail="Test DB Error", status_code=503)\nbackend.app.exceptions.DatabaseError: Test DB Error'}
2025-06-06 20:02:21,906 - httpx - INFO [None] - _send_single_request:1013 - HTTP Request: GET http://testserver/test_exc/database_error "HTTP/1.1 503 Service Unavailable"
2025-06-06 20:02:21,913 - backend.app.main - ERROR [None] - app_exception_handler:134 - {'type': 'ExternalAPIError', 'detail': 'Test External API Error', 'status_code': 504, 'path': '/test_exc/external_api_error', 'method': 'GET', 'event': 'Application error occurred', 'request_id': 'bd68c3cb-c3ea-472b-abb1-6112c0677a0b', 'logger': 'backend.app.main', 'level': 'error', 'timestamp': '2025-06-06T20:02:21.913239Z', 'exception': 'Traceback (most recent call last):\n  File "/home/swebot/.local/lib/python3.10/site-packages/starlette/middleware/exceptions.py", line 68, in __call__\n    await self.app(scope, receive, sender)\n  File "/home/swebot/.local/lib/python3.10/site-packages/fastapi/middleware/asyncexitstack.py", line 20, in __call__\n    raise e\n  File "/home/swebot/.local/lib/python3.10/site-packages/fastapi/middleware/asyncexitstack.py", line 17, in __call__\n    await self.app(scope, receive, send)\n  File "/home/swebot/.local/lib/python3.10/site-packages/starlette/routing.py", line 718, in __call__\n    await route.handle(scope, receive, send)\n  File "/home/swebot/.local/lib/python3.10/site-packages/starlette/routing.py", line 276, in handle\n    await self.app(scope, receive, send)\n  File "/home/swebot/.local/lib/python3.10/site-packages/starlette/routing.py", line 66, in app\n    response = await func(request)\n  File "/home/swebot/.local/lib/python3.10/site-packages/fastapi/routing.py", line 274, in app\n    raw_response = await run_endpoint_function(\n  File "/home/swebot/.local/lib/python3.10/site-packages/fastapi/routing.py", line 191, in run_endpoint_function\n    return await dependant.call(**values)\n  File "/app/backend/tests/integration/test_main_exception_handling.py", line 32, in route_raises_external_api_error\n    raise ExternalAPIError(detail="Test External API Error", status_code=504)\nbackend.app.exceptions.ExternalAPIError: Test External API Error'}
2025-06-06 20:02:21,916 - httpx - INFO [None] - _send_single_request:1013 - HTTP Request: GET http://testserver/test_exc/external_api_error "HTTP/1.1 504 Gateway Timeout"
2025-06-06 20:02:21,923 - backend.app.main - ERROR [None] - app_exception_handler:134 - {'type': 'AuthenticationError', 'detail': 'Test Auth Error', 'status_code': 401, 'path': '/test_exc/authentication_error', 'method': 'GET', 'event': 'Application error occurred', 'request_id': '55f54673-2063-4315-80f3-47251517af1d', 'logger': 'backend.app.main', 'level': 'error', 'timestamp': '2025-06-06T20:02:21.922992Z', 'exception': 'Traceback (most recent call last):\n  File "/home/swebot/.local/lib/python3.10/site-packages/starlette/middleware/exceptions.py", line 68, in __call__\n    await self.app(scope, receive, sender)\n  File "/home/swebot/.local/lib/python3.10/site-packages/fastapi/middleware/asyncexitstack.py", line 20, in __call__\n    raise e\n  File "/home/swebot/.local/lib/python3.10/site-packages/fastapi/middleware/asyncexitstack.py", line 17, in __call__\n    await self.app(scope, receive, send)\n  File "/home/swebot/.local/lib/python3.10/site-packages/starlette/routing.py", line 718, in __call__\n    await route.handle(scope, receive, send)\n  File "/home/swebot/.local/lib/python3.10/site-packages/starlette/routing.py", line 276, in handle\n    await self.app(scope, receive, send)\n  File "/home/swebot/.local/lib/python3.10/site-packages/starlette/routing.py", line 66, in app\n    response = await func(request)\n  File "/home/swebot/.local/lib/python3.10/site-packages/fastapi/routing.py", line 274, in app\n    raw_response = await run_endpoint_function(\n  File "/home/swebot/.local/lib/python3.10/site-packages/fastapi/routing.py", line 191, in run_endpoint_function\n    return await dependant.call(**values)\n  File "/app/backend/tests/integration/test_main_exception_handling.py", line 36, in route_raises_authentication_error\n    raise AuthenticationError(detail="Test Auth Error", status_code=401)\nbackend.app.exceptions.AuthenticationError: Test Auth Error'}
2025-06-06 20:02:21,926 - httpx - INFO [None] - _send_single_request:1013 - HTTP Request: GET http://testserver/test_exc/authentication_error "HTTP/1.1 401 Unauthorized"
2025-06-06 20:02:21,932 - backend.app.main - ERROR [None] - app_exception_handler:134 - {'type': 'NotFoundError', 'detail': 'Test Not Found Error', 'status_code': 404, 'path': '/test_exc/not_found_error', 'method': 'GET', 'event': 'Application error occurred', 'request_id': 'b2a268a9-f1ab-4197-ae27-aa26f3e04043', 'logger': 'backend.app.main', 'level': 'error', 'timestamp': '2025-06-06T20:02:21.932302Z', 'exception': 'Traceback (most recent call last):\n  File "/home/swebot/.local/lib/python3.10/site-packages/starlette/middleware/exceptions.py", line 68, in __call__\n    await self.app(scope, receive, sender)\n  File "/home/swebot/.local/lib/python3.10/site-packages/fastapi/middleware/asyncexitstack.py", line 20, in __call__\n    raise e\n  File "/home/swebot/.local/lib/python3.10/site-packages/fastapi/middleware/asyncexitstack.py", line 17, in __call__\n    await self.app(scope, receive, send)\n  File "/home/swebot/.local/lib/python3.10/site-packages/starlette/routing.py", line 718, in __call__\n    await route.handle(scope, receive, send)\n  File "/home/swebot/.local/lib/python3.10/site-packages/starlette/routing.py", line 276, in handle\n    await self.app(scope, receive, send)\n  File "/home/swebot/.local/lib/python3.10/site-packages/starlette/routing.py", line 66, in app\n    response = await func(request)\n  File "/home/swebot/.local/lib/python3.10/site-packages/fastapi/routing.py", line 274, in app\n    raw_response = await run_endpoint_function(\n  File "/home/swebot/.local/lib/python3.10/site-packages/fastapi/routing.py", line 191, in run_endpoint_function\n    return await dependant.call(**values)\n  File "/app/backend/tests/integration/test_main_exception_handling.py", line 40, in route_raises_not_found_error\n    raise NotFoundError(detail="Test Not Found Error", status_code=404)\nbackend.app.exceptions.NotFoundError: Test Not Found Error'}
2025-06-06 20:02:21,935 - httpx - INFO [None] - _send_single_request:1013 - HTTP Request: GET http://testserver/test_exc/not_found_error "HTTP/1.1 404 Not Found"
2025-06-06 20:02:21,942 - backend.app.main - ERROR [None] - app_exception_handler:134 - {'type': 'BusinessLogicError', 'detail': 'Test Business Logic Error', 'status_code': 400, 'path': '/test_exc/business_logic_error', 'method': 'GET', 'event': 'Application error occurred', 'request_id': 'fc074867-fb43-457d-a297-17d2f6b079e7', 'logger': 'backend.app.main', 'level': 'error', 'timestamp': '2025-06-06T20:02:21.942367Z', 'exception': 'Traceback (most recent call last):\n  File "/home/swebot/.local/lib/python3.10/site-packages/starlette/middleware/exceptions.py", line 68, in __call__\n    await self.app(scope, receive, sender)\n  File "/home/swebot/.local/lib/python3.10/site-packages/fastapi/middleware/asyncexitstack.py", line 20, in __call__\n    raise e\n  File "/home/swebot/.local/lib/python3.10/site-packages/fastapi/middleware/asyncexitstack.py", line 17, in __call__\n    await self.app(scope, receive, send)\n  File "/home/swebot/.local/lib/python3.10/site-packages/starlette/routing.py", line 718, in __call__\n    await route.handle(scope, receive, send)\n  File "/home/swebot/.local/lib/python3.10/site-packages/starlette/routing.py", line 276, in handle\n    await self.app(scope, receive, send)\n  File "/home/swebot/.local/lib/python3.10/site-packages/starlette/routing.py", line 66, in app\n    response = await func(request)\n  File "/home/swebot/.local/lib/python3.10/site-packages/fastapi/routing.py", line 274, in app\n    raw_response = await run_endpoint_function(\n  File "/home/swebot/.local/lib/python3.10/site-packages/fastapi/routing.py", line 191, in run_endpoint_function\n    return await dependant.call(**values)\n  File "/app/backend/tests/integration/test_main_exception_handling.py", line 44, in route_raises_business_logic_error\n    raise BusinessLogicError(detail="Test Business Logic Error", status_code=400)\nbackend.app.exceptions.BusinessLogicError: Test Business Logic Error'}
2025-06-06 20:02:21,946 - httpx - INFO [None] - _send_single_request:1013 - HTTP Request: GET http://testserver/test_exc/business_logic_error "HTTP/1.1 400 Bad Request"
2025-06-06 20:02:21,952 - backend.app.main - ERROR [None] - app_exception_handler:134 - {'type': 'AppException', 'detail': 'Generic App Test Error', 'status_code': 418, 'path': '/test_exc/app_exception_generic', 'method': 'GET', 'event': 'Application error occurred', 'request_id': 'fae6a58c-6705-45de-b45d-f0ee955f5902', 'logger': 'backend.app.main', 'level': 'error', 'timestamp': '2025-06-06T20:02:21.951863Z', 'exception': 'Traceback (most recent call last):\n  File "/home/swebot/.local/lib/python3.10/site-packages/starlette/middleware/exceptions.py", line 68, in __call__\n    await self.app(scope, receive, sender)\n  File "/home/swebot/.local/lib/python3.10/site-packages/fastapi/middleware/asyncexitstack.py", line 20, in __call__\n    raise e\n  File "/home/swebot/.local/lib/python3.10/site-packages/fastapi/middleware/asyncexitstack.py", line 17, in __call__\n    await self.app(scope, receive, send)\n  File "/home/swebot/.local/lib/python3.10/site-packages/starlette/routing.py", line 718, in __call__\n    await route.handle(scope, receive, send)\n  File "/home/swebot/.local/lib/python3.10/site-packages/starlette/routing.py", line 276, in handle\n    await self.app(scope, receive, send)\n  File "/home/swebot/.local/lib/python3.10/site-packages/starlette/routing.py", line 66, in app\n    response = await func(request)\n  File "/home/swebot/.local/lib/python3.10/site-packages/fastapi/routing.py", line 274, in app\n    raw_response = await run_endpoint_function(\n  File "/home/swebot/.local/lib/python3.10/site-packages/fastapi/routing.py", line 191, in run_endpoint_function\n    return await dependant.call(**values)\n  File "/app/backend/tests/integration/test_main_exception_handling.py", line 48, in route_raises_app_exception_generic\n    raise AppException(detail="Generic App Test Error", status_code=418)\nbackend.app.exceptions.AppException: Generic App Test Error'}
2025-06-06 20:02:21,955 - httpx - INFO [None] - _send_single_request:1013 - HTTP Request: GET http://testserver/test_exc/app_exception_generic "HTTP/1.1 418 I'm a teapot"
2025-06-06 20:02:21,964 - httpx - INFO [None] - _send_single_request:1013 - HTTP Request: GET http://testserver/ "HTTP/1.1 200 OK"
2025-06-06 20:02:21,971 - httpx - INFO [None] - _send_single_request:1013 - HTTP Request: GET http://testserver/ "HTTP/1.1 200 OK"
2025-06-06 20:05:18,479 - pulseway_backend.logging_config - INFO [None] - setup_logging:86 - {'log_level': 'INFO', 'event': 'Logging setup complete.', 'logger': 'pulseway_backend.logging_config', 'level': 'info', 'timestamp': '2025-06-06T20:05:18.479419Z'}
2025-06-06 20:05:18,713 - backend.app.main - ERROR [None] - app_exception_handler:134 - {'type': 'DatabaseError', 'detail': 'Test DB Error', 'status_code': 503, 'path': '/test_exc/database_error', 'method': 'GET', 'event': 'Application error occurred', 'request_id': 'cd0d3519-bdd8-4f00-909e-5f7b6655180f', 'logger': 'backend.app.main', 'level': 'error', 'timestamp': '2025-06-06T20:05:18.711835Z', 'exception': 'Traceback (most recent call last):\n  File "/home/swebot/.local/lib/python3.10/site-packages/starlette/middleware/exceptions.py", line 68, in __call__\n    await self.app(scope, receive, sender)\n  File "/home/swebot/.local/lib/python3.10/site-packages/fastapi/middleware/asyncexitstack.py", line 20, in __call__\n    raise e\n  File "/home/swebot/.local/lib/python3.10/site-packages/fastapi/middleware/asyncexitstack.py", line 17, in __call__\n    await self.app(scope, receive, send)\n  File "/home/swebot/.local/lib/python3.10/site-packages/starlette/routing.py", line 718, in __call__\n    await route.handle(scope, receive, send)\n  File "/home/swebot/.local/lib/python3.10/site-packages/starlette/routing.py", line 276, in handle\n    await self.app(scope, receive, send)\n  File "/home/swebot/.local/lib/python3.10/site-packages/starlette/routing.py", line 66, in app\n    response = await func(request)\n  File "/home/swebot/.local/lib/python3.10/site-packages/fastapi/routing.py", line 274, in app\n    raw_response = await run_endpoint_function(\n  File "/home/swebot/.local/lib/python3.10/site-packages/fastapi/routing.py", line 191, in run_endpoint_function\n    return await dependant.call(**values)\n  File "/app/backend/tests/integration/test_main_exception_handling.py", line 28, in route_raises_database_error\n    raise DatabaseError(detail="Test DB Error", status_code=503)\nbackend.app.exceptions.DatabaseError: Test DB Error'}
2025-06-06 20:05:18,716 - httpx - INFO [None] - _send_single_request:1013 - HTTP Request: GET http://testserver/test_exc/database_error "HTTP/1.1 503 Service Unavailable"
2025-06-06 20:05:18,722 - backend.app.main - ERROR [None] - app_exception_handler:134 - {'type': 'ExternalAPIError', 'detail': 'Test External API Error', 'status_code': 504, 'path': '/test_exc/external_api_error', 'method': 'GET', 'event': 'Application error occurred', 'request_id': '858dc9d9-c094-46b1-b23c-836769fd0f7b', 'logger': 'backend.app.main', 'level': 'error', 'timestamp': '2025-06-06T20:05:18.722215Z', 'exception': 'Traceback (most recent call last):\n  File "/home/swebot/.local/lib/python3.10/site-packages/starlette/middleware/exceptions.py", line 68, in __call__\n    await self.app(scope, receive, sender)\n  File "/home/swebot/.local/lib/python3.10/site-packages/fastapi/middleware/asyncexitstack.py", line 20, in __call__\n    raise e\n  File "/home/swebot/.local/lib/python3.10/site-packages/fastapi/middleware/asyncexitstack.py", line 17, in __call__\n    await self.app(scope, receive, send)\n  File "/home/swebot/.local/lib/python3.10/site-packages/starlette/routing.py", line 718, in __call__\n    await route.handle(scope, receive, send)\n  File "/home/swebot/.local/lib/python3.10/site-packages/starlette/routing.py", line 276, in handle\n    await self.app(scope, receive, send)\n  File "/home/swebot/.local/lib/python3.10/site-packages/starlette/routing.py", line 66, in app\n    response = await func(request)\n  File "/home/swebot/.local/lib/python3.10/site-packages/fastapi/routing.py", line 274, in app\n    raw_response = await run_endpoint_function(\n  File "/home/swebot/.local/lib/python3.10/site-packages/fastapi/routing.py", line 191, in run_endpoint_function\n    return await dependant.call(**values)\n  File "/app/backend/tests/integration/test_main_exception_handling.py", line 32, in route_raises_external_api_error\n    raise ExternalAPIError(detail="Test External API Error", status_code=504)\nbackend.app.exceptions.ExternalAPIError: Test External API Error'}
2025-06-06 20:05:18,724 - httpx - INFO [None] - _send_single_request:1013 - HTTP Request: GET http://testserver/test_exc/external_api_error "HTTP/1.1 504 Gateway Timeout"
2025-06-06 20:05:18,730 - backend.app.main - ERROR [None] - app_exception_handler:134 - {'type': 'AuthenticationError', 'detail': 'Test Auth Error', 'status_code': 401, 'path': '/test_exc/authentication_error', 'method': 'GET', 'event': 'Application error occurred', 'request_id': '1ba4bae0-1698-4d62-95cb-ad8b161fb528', 'logger': 'backend.app.main', 'level': 'error', 'timestamp': '2025-06-06T20:05:18.729725Z', 'exception': 'Traceback (most recent call last):\n  File "/home/swebot/.local/lib/python3.10/site-packages/starlette/middleware/exceptions.py", line 68, in __call__\n    await self.app(scope, receive, sender)\n  File "/home/swebot/.local/lib/python3.10/site-packages/fastapi/middleware/asyncexitstack.py", line 20, in __call__\n    raise e\n  File "/home/swebot/.local/lib/python3.10/site-packages/fastapi/middleware/asyncexitstack.py", line 17, in __call__\n    await self.app(scope, receive, send)\n  File "/home/swebot/.local/lib/python3.10/site-packages/starlette/routing.py", line 718, in __call__\n    await route.handle(scope, receive, send)\n  File "/home/swebot/.local/lib/python3.10/site-packages/starlette/routing.py", line 276, in handle\n    await self.app(scope, receive, send)\n  File "/home/swebot/.local/lib/python3.10/site-packages/starlette/routing.py", line 66, in app\n    response = await func(request)\n  File "/home/swebot/.local/lib/python3.10/site-packages/fastapi/routing.py", line 274, in app\n    raw_response = await run_endpoint_function(\n  File "/home/swebot/.local/lib/python3.10/site-packages/fastapi/routing.py", line 191, in run_endpoint_function\n    return await dependant.call(**values)\n  File "/app/backend/tests/integration/test_main_exception_handling.py", line 36, in route_raises_authentication_error\n    raise AuthenticationError(detail="Test Auth Error", status_code=401)\nbackend.app.exceptions.AuthenticationError: Test Auth Error'}
2025-06-06 20:05:18,732 - httpx - INFO [None] - _send_single_request:1013 - HTTP Request: GET http://testserver/test_exc/authentication_error "HTTP/1.1 401 Unauthorized"
2025-06-06 20:05:18,738 - backend.app.main - ERROR [None] - app_exception_handler:134 - {'type': 'NotFoundError', 'detail': 'Test Not Found Error', 'status_code': 404, 'path': '/test_exc/not_found_error', 'method': 'GET', 'event': 'Application error occurred', 'request_id': '01f11b64-f502-4441-b17d-b6bf90e5bcfa', 'logger': 'backend.app.main', 'level': 'error', 'timestamp': '2025-06-06T20:05:18.737819Z', 'exception': 'Traceback (most recent call last):\n  File "/home/swebot/.local/lib/python3.10/site-packages/starlette/middleware/exceptions.py", line 68, in __call__\n    await self.app(scope, receive, sender)\n  File "/home/swebot/.local/lib/python3.10/site-packages/fastapi/middleware/asyncexitstack.py", line 20, in __call__\n    raise e\n  File "/home/swebot/.local/lib/python3.10/site-packages/fastapi/middleware/asyncexitstack.py", line 17, in __call__\n    await self.app(scope, receive, send)\n  File "/home/swebot/.local/lib/python3.10/site-packages/starlette/routing.py", line 718, in __call__\n    await route.handle(scope, receive, send)\n  File "/home/swebot/.local/lib/python3.10/site-packages/starlette/routing.py", line 276, in handle\n    await self.app(scope, receive, send)\n  File "/home/swebot/.local/lib/python3.10/site-packages/starlette/routing.py", line 66, in app\n    response = await func(request)\n  File "/home/swebot/.local/lib/python3.10/site-packages/fastapi/routing.py", line 274, in app\n    raw_response = await run_endpoint_function(\n  File "/home/swebot/.local/lib/python3.10/site-packages/fastapi/routing.py", line 191, in run_endpoint_function\n    return await dependant.call(**values)\n  File "/app/backend/tests/integration/test_main_exception_handling.py", line 40, in route_raises_not_found_error\n    raise NotFoundError(detail="Test Not Found Error", status_code=404)\nbackend.app.exceptions.NotFoundError: Test Not Found Error'}
2025-06-06 20:05:18,740 - httpx - INFO [None] - _send_single_request:1013 - HTTP Request: GET http://testserver/test_exc/not_found_error "HTTP/1.1 404 Not Found"
2025-06-06 20:05:18,745 - backend.app.main - ERROR [None] - app_exception_handler:134 - {'type': 'BusinessLogicError', 'detail': 'Test Business Logic Error', 'status_code': 400, 'path': '/test_exc/business_logic_error', 'method': 'GET', 'event': 'Application error occurred', 'request_id': '5c8551d9-9cb8-4bf1-8bc4-196f3dbd0e4d', 'logger': 'backend.app.main', 'level': 'error', 'timestamp': '2025-06-06T20:05:18.745644Z', 'exception': 'Traceback (most recent call last):\n  File "/home/swebot/.local/lib/python3.10/site-packages/starlette/middleware/exceptions.py", line 68, in __call__\n    await self.app(scope, receive, sender)\n  File "/home/swebot/.local/lib/python3.10/site-packages/fastapi/middleware/asyncexitstack.py", line 20, in __call__\n    raise e\n  File "/home/swebot/.local/lib/python3.10/site-packages/fastapi/middleware/asyncexitstack.py", line 17, in __call__\n    await self.app(scope, receive, send)\n  File "/home/swebot/.local/lib/python3.10/site-packages/starlette/routing.py", line 718, in __call__\n    await route.handle(scope, receive, send)\n  File "/home/swebot/.local/lib/python3.10/site-packages/starlette/routing.py", line 276, in handle\n    await self.app(scope, receive, send)\n  File "/home/swebot/.local/lib/python3.10/site-packages/starlette/routing.py", line 66, in app\n    response = await func(request)\n  File "/home/swebot/.local/lib/python3.10/site-packages/fastapi/routing.py", line 274, in app\n    raw_response = await run_endpoint_function(\n  File "/home/swebot/.local/lib/python3.10/site-packages/fastapi/routing.py", line 191, in run_endpoint_function\n    return await dependant.call(**values)\n  File "/app/backend/tests/integration/test_main_exception_handling.py", line 44, in route_raises_business_logic_error\n    raise BusinessLogicError(detail="Test Business Logic Error", status_code=400)\nbackend.app.exceptions.BusinessLogicError: Test Business Logic Error'}
2025-06-06 20:05:18,748 - httpx - INFO [None] - _send_single_request:1013 - HTTP Request: GET http://testserver/test_exc/business_logic_error "HTTP/1.1 400 Bad Request"
2025-06-06 20:05:18,753 - backend.app.main - ERROR [None] - app_exception_handler:134 - {'type': 'AppException', 'detail': 'Generic App Test Error', 'status_code': 418, 'path': '/test_exc/app_exception_generic', 'method': 'GET', 'event': 'Application error occurred', 'request_id': '57aa8546-cf7d-4b7c-96f3-24d544a1cf99', 'logger': 'backend.app.main', 'level': 'error', 'timestamp': '2025-06-06T20:05:18.753185Z', 'exception': 'Traceback (most recent call last):\n  File "/home/swebot/.local/lib/python3.10/site-packages/starlette/middleware/exceptions.py", line 68, in __call__\n    await self.app(scope, receive, sender)\n  File "/home/swebot/.local/lib/python3.10/site-packages/fastapi/middleware/asyncexitstack.py", line 20, in __call__\n    raise e\n  File "/home/swebot/.local/lib/python3.10/site-packages/fastapi/middleware/asyncexitstack.py", line 17, in __call__\n    await self.app(scope, receive, send)\n  File "/home/swebot/.local/lib/python3.10/site-packages/starlette/routing.py", line 718, in __call__\n    await route.handle(scope, receive, send)\n  File "/home/swebot/.local/lib/python3.10/site-packages/starlette/routing.py", line 276, in handle\n    await self.app(scope, receive, send)\n  File "/home/swebot/.local/lib/python3.10/site-packages/starlette/routing.py", line 66, in app\n    response = await func(request)\n  File "/home/swebot/.local/lib/python3.10/site-packages/fastapi/routing.py", line 274, in app\n    raw_response = await run_endpoint_function(\n  File "/home/swebot/.local/lib/python3.10/site-packages/fastapi/routing.py", line 191, in run_endpoint_function\n    return await dependant.call(**values)\n  File "/app/backend/tests/integration/test_main_exception_handling.py", line 48, in route_raises_app_exception_generic\n    raise AppException(detail="Generic App Test Error", status_code=418)\nbackend.app.exceptions.AppException: Generic App Test Error'}
2025-06-06 20:05:18,755 - httpx - INFO [None] - _send_single_request:1013 - HTTP Request: GET http://testserver/test_exc/app_exception_generic "HTTP/1.1 418 I'm a teapot"
2025-06-06 20:05:18,763 - httpx - INFO [None] - _send_single_request:1013 - HTTP Request: GET http://testserver/ "HTTP/1.1 200 OK"
2025-06-06 20:05:18,766 - asyncio - DEBUG [None] - __init__:54 - Using selector: EpollSelector
2025-06-06 20:05:18,768 - backend.app.main - DEBUG [None] - request_tracing_middleware:166 - {'method': 'GET', 'path': '/', 'client_host': 'testclient', 'event': 'Request received', 'request_id': 'b501aea2-3d05-4526-aa5b-04d44f6f2c82', 'logger': 'backend.app.main', 'level': 'debug', 'timestamp': '2025-06-06T20:05:18.768462Z'}
2025-06-06 20:05:18,769 - backend.app.main - DEBUG [None] - root:203 - {'event': 'Root health check requested', 'request_id': 'b501aea2-3d05-4526-aa5b-04d44f6f2c82', 'logger': 'backend.app.main', 'level': 'debug', 'timestamp': '2025-06-06T20:05:18.769752Z'}
2025-06-06 20:05:18,770 - backend.app.main - DEBUG [None] - request_tracing_middleware:172 - {'method': 'GET', 'path': '/', 'status_code': 200, 'event': 'Request finished', 'request_id': 'b501aea2-3d05-4526-aa5b-04d44f6f2c82', 'logger': 'backend.app.main', 'level': 'debug', 'timestamp': '2025-06-06T20:05:18.770504Z'}
2025-06-06 20:05:18,773 - httpx - INFO [None] - _send_single_request:1013 - HTTP Request: GET http://testserver/ "HTTP/1.1 200 OK"
2025-06-06 20:06:03,340 - pulseway_backend.logging_config - INFO [None] - setup_logging:86 - {'log_level': 'INFO', 'event': 'Logging setup complete.', 'logger': 'pulseway_backend.logging_config', 'level': 'info', 'timestamp': '2025-06-06T20:06:03.340050Z'}
2025-06-06 20:06:03,571 - backend.app.main - ERROR [None] - app_exception_handler:134 - {'type': 'DatabaseError', 'detail': 'Test DB Error', 'status_code': 503, 'path': '/test_exc/database_error', 'method': 'GET', 'event': 'Application error occurred', 'request_id': 'b50975d4-9e4b-467d-b2ca-067d173c86fc', 'logger': 'backend.app.main', 'level': 'error', 'timestamp': '2025-06-06T20:06:03.565941Z', 'exception': 'Traceback (most recent call last):\n  File "/home/swebot/.local/lib/python3.10/site-packages/starlette/middleware/exceptions.py", line 68, in __call__\n    await self.app(scope, receive, sender)\n  File "/home/swebot/.local/lib/python3.10/site-packages/fastapi/middleware/asyncexitstack.py", line 20, in __call__\n    raise e\n  File "/home/swebot/.local/lib/python3.10/site-packages/fastapi/middleware/asyncexitstack.py", line 17, in __call__\n    await self.app(scope, receive, send)\n  File "/home/swebot/.local/lib/python3.10/site-packages/starlette/routing.py", line 718, in __call__\n    await route.handle(scope, receive, send)\n  File "/home/swebot/.local/lib/python3.10/site-packages/starlette/routing.py", line 276, in handle\n    await self.app(scope, receive, send)\n  File "/home/swebot/.local/lib/python3.10/site-packages/starlette/routing.py", line 66, in app\n    response = await func(request)\n  File "/home/swebot/.local/lib/python3.10/site-packages/fastapi/routing.py", line 274, in app\n    raw_response = await run_endpoint_function(\n  File "/home/swebot/.local/lib/python3.10/site-packages/fastapi/routing.py", line 191, in run_endpoint_function\n    return await dependant.call(**values)\n  File "/app/backend/tests/integration/test_main_exception_handling.py", line 28, in route_raises_database_error\n    raise DatabaseError(detail="Test DB Error", status_code=503)\nbackend.app.exceptions.DatabaseError: Test DB Error'}
2025-06-06 20:06:03,575 - httpx - INFO [None] - _send_single_request:1013 - HTTP Request: GET http://testserver/test_exc/database_error "HTTP/1.1 503 Service Unavailable"
2025-06-06 20:06:03,580 - backend.app.main - ERROR [None] - app_exception_handler:134 - {'type': 'ExternalAPIError', 'detail': 'Test External API Error', 'status_code': 504, 'path': '/test_exc/external_api_error', 'method': 'GET', 'event': 'Application error occurred', 'request_id': 'd7e85000-5801-4168-a33f-7f97cc80a841', 'logger': 'backend.app.main', 'level': 'error', 'timestamp': '2025-06-06T20:06:03.580505Z', 'exception': 'Traceback (most recent call last):\n  File "/home/swebot/.local/lib/python3.10/site-packages/starlette/middleware/exceptions.py", line 68, in __call__\n    await self.app(scope, receive, sender)\n  File "/home/swebot/.local/lib/python3.10/site-packages/fastapi/middleware/asyncexitstack.py", line 20, in __call__\n    raise e\n  File "/home/swebot/.local/lib/python3.10/site-packages/fastapi/middleware/asyncexitstack.py", line 17, in __call__\n    await self.app(scope, receive, send)\n  File "/home/swebot/.local/lib/python3.10/site-packages/starlette/routing.py", line 718, in __call__\n    await route.handle(scope, receive, send)\n  File "/home/swebot/.local/lib/python3.10/site-packages/starlette/routing.py", line 276, in handle\n    await self.app(scope, receive, send)\n  File "/home/swebot/.local/lib/python3.10/site-packages/starlette/routing.py", line 66, in app\n    response = await func(request)\n  File "/home/swebot/.local/lib/python3.10/site-packages/fastapi/routing.py", line 274, in app\n    raw_response = await run_endpoint_function(\n  File "/home/swebot/.local/lib/python3.10/site-packages/fastapi/routing.py", line 191, in run_endpoint_function\n    return await dependant.call(**values)\n  File "/app/backend/tests/integration/test_main_exception_handling.py", line 32, in route_raises_external_api_error\n    raise ExternalAPIError(detail="Test External API Error", status_code=504)\nbackend.app.exceptions.ExternalAPIError: Test External API Error'}
2025-06-06 20:06:03,583 - httpx - INFO [None] - _send_single_request:1013 - HTTP Request: GET http://testserver/test_exc/external_api_error "HTTP/1.1 504 Gateway Timeout"
2025-06-06 20:06:03,588 - backend.app.main - ERROR [None] - app_exception_handler:134 - {'type': 'AuthenticationError', 'detail': 'Test Auth Error', 'status_code': 401, 'path': '/test_exc/authentication_error', 'method': 'GET', 'event': 'Application error occurred', 'request_id': '11b0702a-1a70-4230-8517-a1c4907af78f', 'logger': 'backend.app.main', 'level': 'error', 'timestamp': '2025-06-06T20:06:03.588217Z', 'exception': 'Traceback (most recent call last):\n  File "/home/swebot/.local/lib/python3.10/site-packages/starlette/middleware/exceptions.py", line 68, in __call__\n    await self.app(scope, receive, sender)\n  File "/home/swebot/.local/lib/python3.10/site-packages/fastapi/middleware/asyncexitstack.py", line 20, in __call__\n    raise e\n  File "/home/swebot/.local/lib/python3.10/site-packages/fastapi/middleware/asyncexitstack.py", line 17, in __call__\n    await self.app(scope, receive, send)\n  File "/home/swebot/.local/lib/python3.10/site-packages/starlette/routing.py", line 718, in __call__\n    await route.handle(scope, receive, send)\n  File "/home/swebot/.local/lib/python3.10/site-packages/starlette/routing.py", line 276, in handle\n    await self.app(scope, receive, send)\n  File "/home/swebot/.local/lib/python3.10/site-packages/starlette/routing.py", line 66, in app\n    response = await func(request)\n  File "/home/swebot/.local/lib/python3.10/site-packages/fastapi/routing.py", line 274, in app\n    raw_response = await run_endpoint_function(\n  File "/home/swebot/.local/lib/python3.10/site-packages/fastapi/routing.py", line 191, in run_endpoint_function\n    return await dependant.call(**values)\n  File "/app/backend/tests/integration/test_main_exception_handling.py", line 36, in route_raises_authentication_error\n    raise AuthenticationError(detail="Test Auth Error", status_code=401)\nbackend.app.exceptions.AuthenticationError: Test Auth Error'}
2025-06-06 20:06:03,591 - httpx - INFO [None] - _send_single_request:1013 - HTTP Request: GET http://testserver/test_exc/authentication_error "HTTP/1.1 401 Unauthorized"
2025-06-06 20:06:03,596 - backend.app.main - ERROR [None] - app_exception_handler:134 - {'type': 'NotFoundError', 'detail': 'Test Not Found Error', 'status_code': 404, 'path': '/test_exc/not_found_error', 'method': 'GET', 'event': 'Application error occurred', 'request_id': '3d4e91a4-8063-4dc5-9c26-bbbf47045a33', 'logger': 'backend.app.main', 'level': 'error', 'timestamp': '2025-06-06T20:06:03.596517Z', 'exception': 'Traceback (most recent call last):\n  File "/home/swebot/.local/lib/python3.10/site-packages/starlette/middleware/exceptions.py", line 68, in __call__\n    await self.app(scope, receive, sender)\n  File "/home/swebot/.local/lib/python3.10/site-packages/fastapi/middleware/asyncexitstack.py", line 20, in __call__\n    raise e\n  File "/home/swebot/.local/lib/python3.10/site-packages/fastapi/middleware/asyncexitstack.py", line 17, in __call__\n    await self.app(scope, receive, send)\n  File "/home/swebot/.local/lib/python3.10/site-packages/starlette/routing.py", line 718, in __call__\n    await route.handle(scope, receive, send)\n  File "/home/swebot/.local/lib/python3.10/site-packages/starlette/routing.py", line 276, in handle\n    await self.app(scope, receive, send)\n  File "/home/swebot/.local/lib/python3.10/site-packages/starlette/routing.py", line 66, in app\n    response = await func(request)\n  File "/home/swebot/.local/lib/python3.10/site-packages/fastapi/routing.py", line 274, in app\n    raw_response = await run_endpoint_function(\n  File "/home/swebot/.local/lib/python3.10/site-packages/fastapi/routing.py", line 191, in run_endpoint_function\n    return await dependant.call(**values)\n  File "/app/backend/tests/integration/test_main_exception_handling.py", line 40, in route_raises_not_found_error\n    raise NotFoundError(detail="Test Not Found Error", status_code=404)\nbackend.app.exceptions.NotFoundError: Test Not Found Error'}
2025-06-06 20:06:03,599 - httpx - INFO [None] - _send_single_request:1013 - HTTP Request: GET http://testserver/test_exc/not_found_error "HTTP/1.1 404 Not Found"
2025-06-06 20:06:03,604 - backend.app.main - ERROR [None] - app_exception_handler:134 - {'type': 'BusinessLogicError', 'detail': 'Test Business Logic Error', 'status_code': 400, 'path': '/test_exc/business_logic_error', 'method': 'GET', 'event': 'Application error occurred', 'request_id': 'a5f340a3-9138-4882-ab7b-75c38ec72087', 'logger': 'backend.app.main', 'level': 'error', 'timestamp': '2025-06-06T20:06:03.604178Z', 'exception': 'Traceback (most recent call last):\n  File "/home/swebot/.local/lib/python3.10/site-packages/starlette/middleware/exceptions.py", line 68, in __call__\n    await self.app(scope, receive, sender)\n  File "/home/swebot/.local/lib/python3.10/site-packages/fastapi/middleware/asyncexitstack.py", line 20, in __call__\n    raise e\n  File "/home/swebot/.local/lib/python3.10/site-packages/fastapi/middleware/asyncexitstack.py", line 17, in __call__\n    await self.app(scope, receive, send)\n  File "/home/swebot/.local/lib/python3.10/site-packages/starlette/routing.py", line 718, in __call__\n    await route.handle(scope, receive, send)\n  File "/home/swebot/.local/lib/python3.10/site-packages/starlette/routing.py", line 276, in handle\n    await self.app(scope, receive, send)\n  File "/home/swebot/.local/lib/python3.10/site-packages/starlette/routing.py", line 66, in app\n    response = await func(request)\n  File "/home/swebot/.local/lib/python3.10/site-packages/fastapi/routing.py", line 274, in app\n    raw_response = await run_endpoint_function(\n  File "/home/swebot/.local/lib/python3.10/site-packages/fastapi/routing.py", line 191, in run_endpoint_function\n    return await dependant.call(**values)\n  File "/app/backend/tests/integration/test_main_exception_handling.py", line 44, in route_raises_business_logic_error\n    raise BusinessLogicError(detail="Test Business Logic Error", status_code=400)\nbackend.app.exceptions.BusinessLogicError: Test Business Logic Error'}
2025-06-06 20:06:03,607 - httpx - INFO [None] - _send_single_request:1013 - HTTP Request: GET http://testserver/test_exc/business_logic_error "HTTP/1.1 400 Bad Request"
2025-06-06 20:06:03,612 - backend.app.main - ERROR [None] - app_exception_handler:134 - {'type': 'AppException', 'detail': 'Generic App Test Error', 'status_code': 418, 'path': '/test_exc/app_exception_generic', 'method': 'GET', 'event': 'Application error occurred', 'request_id': 'e6d6017e-92c7-43d7-815c-b301d6c6672b', 'logger': 'backend.app.main', 'level': 'error', 'timestamp': '2025-06-06T20:06:03.611844Z', 'exception': 'Traceback (most recent call last):\n  File "/home/swebot/.local/lib/python3.10/site-packages/starlette/middleware/exceptions.py", line 68, in __call__\n    await self.app(scope, receive, sender)\n  File "/home/swebot/.local/lib/python3.10/site-packages/fastapi/middleware/asyncexitstack.py", line 20, in __call__\n    raise e\n  File "/home/swebot/.local/lib/python3.10/site-packages/fastapi/middleware/asyncexitstack.py", line 17, in __call__\n    await self.app(scope, receive, send)\n  File "/home/swebot/.local/lib/python3.10/site-packages/starlette/routing.py", line 718, in __call__\n    await route.handle(scope, receive, send)\n  File "/home/swebot/.local/lib/python3.10/site-packages/starlette/routing.py", line 276, in handle\n    await self.app(scope, receive, send)\n  File "/home/swebot/.local/lib/python3.10/site-packages/starlette/routing.py", line 66, in app\n    response = await func(request)\n  File "/home/swebot/.local/lib/python3.10/site-packages/fastapi/routing.py", line 274, in app\n    raw_response = await run_endpoint_function(\n  File "/home/swebot/.local/lib/python3.10/site-packages/fastapi/routing.py", line 191, in run_endpoint_function\n    return await dependant.call(**values)\n  File "/app/backend/tests/integration/test_main_exception_handling.py", line 48, in route_raises_app_exception_generic\n    raise AppException(detail="Generic App Test Error", status_code=418)\nbackend.app.exceptions.AppException: Generic App Test Error'}
2025-06-06 20:06:03,614 - httpx - INFO [None] - _send_single_request:1013 - HTTP Request: GET http://testserver/test_exc/app_exception_generic "HTTP/1.1 418 I'm a teapot"
2025-06-06 20:06:03,620 - httpx - INFO [None] - _send_single_request:1013 - HTTP Request: GET http://testserver/ "HTTP/1.1 200 OK"
2025-06-06 20:06:03,622 - asyncio - DEBUG [None] - __init__:54 - Using selector: EpollSelector
2025-06-06 20:06:03,623 - backend.app.main - DEBUG [None] - request_tracing_middleware:166 - {'method': 'GET', 'path': '/', 'client_host': 'testclient', 'event': 'Request received', 'request_id': '3f7483c5-99c1-4269-92f3-2938bd272475', 'logger': 'backend.app.main', 'level': 'debug', 'timestamp': '2025-06-06T20:06:03.623758Z'}
2025-06-06 20:06:03,624 - backend.app.main - DEBUG [None] - root:203 - {'event': 'Root health check requested', 'request_id': '3f7483c5-99c1-4269-92f3-2938bd272475', 'logger': 'backend.app.main', 'level': 'debug', 'timestamp': '2025-06-06T20:06:03.624326Z'}
2025-06-06 20:06:03,624 - backend.app.main - DEBUG [None] - request_tracing_middleware:172 - {'method': 'GET', 'path': '/', 'status_code': 200, 'event': 'Request finished', 'request_id': '3f7483c5-99c1-4269-92f3-2938bd272475', 'logger': 'backend.app.main', 'level': 'debug', 'timestamp': '2025-06-06T20:06:03.624875Z'}
2025-06-06 20:06:03,640 - httpx - INFO [None] - _send_single_request:1013 - HTTP Request: GET http://testserver/ "HTTP/1.1 200 OK"
2025-06-06 20:09:13,291 - pulseway_backend.logging_config - INFO [None] - setup_logging:89 - Logging setup complete.
2025-06-06 20:12:53,043 - pulseway_backend.logging_config - INFO [None] - setup_logging:89 - Logging setup complete.
2025-06-06 20:12:53,296 - backend.app.main - ERROR [27e209f4-9d30-49fb-a373-c148638edc7b] - app_exception_handler:134 - Application error occurred
2025-06-06 20:12:53,299 - httpx - INFO [None] - _send_single_request:1013 - HTTP Request: GET http://testserver/test_exc/database_error "HTTP/1.1 503 Service Unavailable"
2025-06-06 20:12:53,306 - backend.app.main - ERROR [db21e23f-bb5b-4da7-958e-885d2f793060] - app_exception_handler:134 - Application error occurred
2025-06-06 20:12:53,309 - httpx - INFO [None] - _send_single_request:1013 - HTTP Request: GET http://testserver/test_exc/external_api_error "HTTP/1.1 504 Gateway Timeout"
2025-06-06 20:12:53,314 - backend.app.main - ERROR [7a7b4019-3133-4739-b220-2e81a7a7995e] - app_exception_handler:134 - Application error occurred
2025-06-06 20:12:53,317 - httpx - INFO [None] - _send_single_request:1013 - HTTP Request: GET http://testserver/test_exc/authentication_error "HTTP/1.1 401 Unauthorized"
2025-06-06 20:12:53,323 - backend.app.main - ERROR [19fbd55e-000e-425c-bfb9-f27373c831e2] - app_exception_handler:134 - Application error occurred
2025-06-06 20:12:53,325 - httpx - INFO [None] - _send_single_request:1013 - HTTP Request: GET http://testserver/test_exc/not_found_error "HTTP/1.1 404 Not Found"
2025-06-06 20:12:53,331 - backend.app.main - ERROR [90460af7-3be6-4306-aa90-6ba48f9f7c62] - app_exception_handler:134 - Application error occurred
2025-06-06 20:12:53,333 - httpx - INFO [None] - _send_single_request:1013 - HTTP Request: GET http://testserver/test_exc/business_logic_error "HTTP/1.1 400 Bad Request"
2025-06-06 20:12:53,339 - backend.app.main - ERROR [78aef0d9-fada-4f94-8f8e-a6d2bf67376d] - app_exception_handler:134 - Application error occurred
2025-06-06 20:12:53,341 - httpx - INFO [None] - _send_single_request:1013 - HTTP Request: GET http://testserver/test_exc/app_exception_generic "HTTP/1.1 418 I'm a teapot"
2025-06-06 20:12:53,348 - httpx - INFO [None] - _send_single_request:1013 - HTTP Request: GET http://testserver/ "HTTP/1.1 200 OK"
2025-06-06 20:12:53,351 - asyncio - DEBUG [None] - __init__:54 - Using selector: EpollSelector
2025-06-06 20:12:53,352 - backend.app.main - DEBUG [205cfcbd-e45f-4659-87e7-852087b5dd80] - request_tracing_middleware:166 - Request received
2025-06-06 20:12:53,353 - backend.app.main - DEBUG [205cfcbd-e45f-4659-87e7-852087b5dd80] - root:203 - Root health check requested
2025-06-06 20:12:53,353 - backend.app.main - DEBUG [205cfcbd-e45f-4659-87e7-852087b5dd80] - request_tracing_middleware:172 - Request finished
2025-06-06 20:12:53,356 - httpx - INFO [None] - _send_single_request:1013 - HTTP Request: GET http://testserver/ "HTTP/1.1 200 OK"
